test_automation1 (__main__.TestMyAutomation) ... ERROR
test_automation2 (__main__.TestMyAutomation) ... ERROR

======================================================================
ERROR: test_automation1 (__main__.TestMyAutomation)
----------------------------------------------------------------------
Traceback (most recent call last):
  File "C:\Users\mohsi\AppData\Local\Programs\Python\Python39\lib\site-packages\selenium\webdriver\common\service.py", line 71, in start
    self.process = subprocess.Popen(cmd, env=self.env,
  File "C:\Users\mohsi\AppData\Local\Programs\Python\Python39\lib\subprocess.py", line 947, in __init__
    self._execute_child(args, executable, preexec_fn, close_fds,
  File "C:\Users\mohsi\AppData\Local\Programs\Python\Python39\lib\subprocess.py", line 1416, in _execute_child
    hp, ht, pid, tid = _winapi.CreateProcess(executable, args,
FileNotFoundError: [WinError 2] The system cannot find the file specified

During handling of the above exception, another exception occurred:

Traceback (most recent call last):
  File "D:\DESICREW\work\test_code.py", line 13, in test_automation1
    auto1()
  File "D:\DESICREW\work\automate1.py", line 11, in auto1
    driver = webdriver.Chrome(r'C:\Users\jbroh\PycharmProjects\selenium drivers\chromedriver.exe')
  File "C:\Users\mohsi\AppData\Local\Programs\Python\Python39\lib\site-packages\selenium\webdriver\chrome\webdriver.py", line 70, in __init__
    super(WebDriver, self).__init__(DesiredCapabilities.CHROME['browserName'], "goog",
  File "C:\Users\mohsi\AppData\Local\Programs\Python\Python39\lib\site-packages\selenium\webdriver\chromium\webdriver.py", line 89, in __init__
    self.service.start()
  File "C:\Users\mohsi\AppData\Local\Programs\Python\Python39\lib\site-packages\selenium\webdriver\common\service.py", line 81, in start
    raise WebDriverException(
selenium.common.exceptions.WebDriverException: Message: 'chromedriver.exe' executable needs to be in PATH. Please see https://chromedriver.chromium.org/home


======================================================================
ERROR: test_automation2 (__main__.TestMyAutomation)
----------------------------------------------------------------------
Traceback (most recent call last):
  File "C:\Users\mohsi\AppData\Local\Programs\Python\Python39\lib\site-packages\selenium\webdriver\common\service.py", line 71, in start
    self.process = subprocess.Popen(cmd, env=self.env,
  File "C:\Users\mohsi\AppData\Local\Programs\Python\Python39\lib\subprocess.py", line 947, in __init__
    self._execute_child(args, executable, preexec_fn, close_fds,
  File "C:\Users\mohsi\AppData\Local\Programs\Python\Python39\lib\subprocess.py", line 1416, in _execute_child
    hp, ht, pid, tid = _winapi.CreateProcess(executable, args,
FileNotFoundError: [WinError 2] The system cannot find the file specified

During handling of the above exception, another exception occurred:

Traceback (most recent call last):
  File "D:\DESICREW\work\test_code.py", line 16, in test_automation2
    auto2()
  File "D:\DESICREW\work\automate2.py", line 11, in auto2
    driver = webdriver.Chrome(r'C:\Users\jbroh\PycharmProjects\selenium drivers\chromedriver.exe')
  File "C:\Users\mohsi\AppData\Local\Programs\Python\Python39\lib\site-packages\selenium\webdriver\chrome\webdriver.py", line 70, in __init__
    super(WebDriver, self).__init__(DesiredCapabilities.CHROME['browserName'], "goog",
  File "C:\Users\mohsi\AppData\Local\Programs\Python\Python39\lib\site-packages\selenium\webdriver\chromium\webdriver.py", line 89, in __init__
    self.service.start()
  File "C:\Users\mohsi\AppData\Local\Programs\Python\Python39\lib\site-packages\selenium\webdriver\common\service.py", line 81, in start
    raise WebDriverException(
selenium.common.exceptions.WebDriverException: Message: 'chromedriver.exe' executable needs to be in PATH. Please see https://chromedriver.chromium.org/home


----------------------------------------------------------------------
Ran 2 tests in 0.007s

FAILED (errors=2)
